<?xml version="1.0" encoding="utf-8"?><testsuites name="pytest tests"><testsuite name="pytest" errors="1" failures="0" skipped="0" tests="1" time="1.515" timestamp="2025-08-24T15:59:41.247977-05:00" hostname="SanctumKey"><testcase classname="" name="tests.test_fastapi_app" time="0.000"><error message="collection failure">venv\Lib\site-packages\_pytest\python.py:498: in importtestmodule
    mod = import_path(
venv\Lib\site-packages\_pytest\pathlib.py:587: in import_path
    importlib.import_module(module_name)
C:\Program Files\Python313\Lib\importlib\__init__.py:88: in import_module
    return _bootstrap._gcd_import(name[level:], package, level)
           ^^^^^^^^^^^^^^^^^^^^^^^^^^^^^^^^^^^^^^^^^^^^^^^^^^^^
&lt;frozen importlib._bootstrap&gt;:1387: in _gcd_import
    ???
&lt;frozen importlib._bootstrap&gt;:1360: in _find_and_load
    ???
&lt;frozen importlib._bootstrap&gt;:1331: in _find_and_load_unlocked
    ???
&lt;frozen importlib._bootstrap&gt;:935: in _load_unlocked
    ???
venv\Lib\site-packages\_pytest\assertion\rewrite.py:186: in exec_module
    exec(co, module.__dict__)
tests\test_fastapi_app.py:14: in &lt;module&gt;
    from main import app
E     File "C:\projects\bk25\src\main.py", line 91
E       return {
E   IndentationError: unexpected indent</error></testcase></testsuite></testsuites>